<?xml version="1.0" encoding="UTF-8"?>
<testng-results skipped="0" failed="11" total="14" passed="3">
  <reporter-output>
  </reporter-output>
  <suite name="Default suite" duration-ms="994" started-at="2015-05-10T19:57:33Z" finished-at="2015-05-10T19:57:34Z">
    <groups>
    </groups>
    <test name="Default test" duration-ms="994" started-at="2015-05-10T19:57:33Z" finished-at="2015-05-10T19:57:34Z">
      <class name="com.FCI.SWE.ServicesModels.Entitytest">
        <test-method status="PASS" signature="setUp()[pri:0, instance:com.FCI.SWE.ServicesModels.Entitytest@44a38527]" name="setUp" is-config="true" duration-ms="54" started-at="2015-05-10T22:57:33Z" finished-at="2015-05-10T22:57:34Z">
          <reporter-output>
          </reporter-output>
        </test-method> <!-- setUp -->
        <test-method status="FAIL" signature="SearchOnPeopleAdd()[pri:0, instance:com.FCI.SWE.ServicesModels.Entitytest@44a38527]" name="SearchOnPeopleAdd" duration-ms="351" started-at="2015-05-10T22:57:34Z" finished-at="2015-05-10T22:57:34Z">
          <exception class="java.lang.IndexOutOfBoundsException">
            <message>
              <![CDATA[Index: 0, Size: 0]]>
            </message>
            <full-stacktrace>
              <![CDATA[java.lang.IndexOutOfBoundsException: Index: 0, Size: 0
	at java.util.ArrayList.rangeCheck(ArrayList.java:635)
	at java.util.ArrayList.get(ArrayList.java:411)
	at com.FCI.SWE.ServicesModels.Entitytest.SearchOnPeopleAdd(Entitytest.java:77)
	at sun.reflect.NativeMethodAccessorImpl.invoke0(Native Method)
	at sun.reflect.NativeMethodAccessorImpl.invoke(NativeMethodAccessorImpl.java:57)
	at sun.reflect.DelegatingMethodAccessorImpl.invoke(DelegatingMethodAccessorImpl.java:43)
	at java.lang.reflect.Method.invoke(Method.java:606)
	at org.testng.internal.MethodInvocationHelper.invokeMethod(MethodInvocationHelper.java:85)
	at org.testng.internal.Invoker.invokeMethod(Invoker.java:659)
	at org.testng.internal.Invoker.invokeTestMethod(Invoker.java:845)
	at org.testng.internal.Invoker.invokeTestMethods(Invoker.java:1153)
	at org.testng.internal.TestMethodWorker.invokeTestMethods(TestMethodWorker.java:124)
	at org.testng.internal.TestMethodWorker.run(TestMethodWorker.java:108)
	at org.testng.TestRunner.privateRun(TestRunner.java:771)
	at org.testng.TestRunner.run(TestRunner.java:621)
	at org.testng.SuiteRunner.runTest(SuiteRunner.java:352)
	at org.testng.SuiteRunner.runSequentially(SuiteRunner.java:347)
	at org.testng.SuiteRunner.privateRun(SuiteRunner.java:305)
	at org.testng.SuiteRunner.run(SuiteRunner.java:254)
	at org.testng.SuiteRunnerWorker.runSuite(SuiteRunnerWorker.java:52)
	at org.testng.SuiteRunnerWorker.run(SuiteRunnerWorker.java:86)
	at org.testng.TestNG.runSuitesSequentially(TestNG.java:1199)
	at org.testng.TestNG.runSuitesLocally(TestNG.java:1124)
	at org.testng.TestNG.run(TestNG.java:1032)
	at org.testng.remote.RemoteTestNG.run(RemoteTestNG.java:111)
	at org.testng.remote.RemoteTestNG.initAndRun(RemoteTestNG.java:204)
	at org.testng.remote.RemoteTestNG.main(RemoteTestNG.java:175)
]]>
            </full-stacktrace>
          </exception> <!-- java.lang.IndexOutOfBoundsException -->
          <reporter-output>
          </reporter-output>
        </test-method> <!-- SearchOnPeopleAdd -->
        <test-method status="FAIL" signature="activepage()[pri:0, instance:com.FCI.SWE.ServicesModels.Entitytest@44a38527]" name="activepage" duration-ms="23" started-at="2015-05-10T22:57:34Z" finished-at="2015-05-10T22:57:34Z">
          <exception class="java.lang.AssertionError">
            <message>
              <![CDATA[expected [fail] but found [el7]]]>
            </message>
            <full-stacktrace>
              <![CDATA[java.lang.AssertionError: expected [fail] but found [el7]
	at org.testng.Assert.fail(Assert.java:94)
	at org.testng.Assert.failNotEquals(Assert.java:494)
	at org.testng.Assert.assertEquals(Assert.java:123)
	at org.testng.Assert.assertEquals(Assert.java:176)
	at org.testng.Assert.assertEquals(Assert.java:186)
	at com.FCI.SWE.ServicesModels.Entitytest.activepage(Entitytest.java:106)
	at sun.reflect.NativeMethodAccessorImpl.invoke0(Native Method)
	at sun.reflect.NativeMethodAccessorImpl.invoke(NativeMethodAccessorImpl.java:57)
	at sun.reflect.DelegatingMethodAccessorImpl.invoke(DelegatingMethodAccessorImpl.java:43)
	at java.lang.reflect.Method.invoke(Method.java:606)
	at org.testng.internal.MethodInvocationHelper.invokeMethod(MethodInvocationHelper.java:85)
	at org.testng.internal.Invoker.invokeMethod(Invoker.java:659)
	at org.testng.internal.Invoker.invokeTestMethod(Invoker.java:845)
	at org.testng.internal.Invoker.invokeTestMethods(Invoker.java:1153)
	at org.testng.internal.TestMethodWorker.invokeTestMethods(TestMethodWorker.java:124)
	at org.testng.internal.TestMethodWorker.run(TestMethodWorker.java:108)
	at org.testng.TestRunner.privateRun(TestRunner.java:771)
	at org.testng.TestRunner.run(TestRunner.java:621)
	at org.testng.SuiteRunner.runTest(SuiteRunner.java:352)
	at org.testng.SuiteRunner.runSequentially(SuiteRunner.java:347)
	at org.testng.SuiteRunner.privateRun(SuiteRunner.java:305)
	at org.testng.SuiteRunner.run(SuiteRunner.java:254)
	at org.testng.SuiteRunnerWorker.runSuite(SuiteRunnerWorker.java:52)
	at org.testng.SuiteRunnerWorker.run(SuiteRunnerWorker.java:86)
	at org.testng.TestNG.runSuitesSequentially(TestNG.java:1199)
	at org.testng.TestNG.runSuitesLocally(TestNG.java:1124)
	at org.testng.TestNG.run(TestNG.java:1032)
	at org.testng.remote.RemoteTestNG.run(RemoteTestNG.java:111)
	at org.testng.remote.RemoteTestNG.initAndRun(RemoteTestNG.java:204)
	at org.testng.remote.RemoteTestNG.main(RemoteTestNG.java:175)
]]>
            </full-stacktrace>
          </exception> <!-- java.lang.AssertionError -->
          <reporter-output>
          </reporter-output>
        </test-method> <!-- activepage -->
        <test-method status="FAIL" signature="chat_message()[pri:0, instance:com.FCI.SWE.ServicesModels.Entitytest@44a38527]" name="chat_message" duration-ms="2" started-at="2015-05-10T22:57:34Z" finished-at="2015-05-10T22:57:34Z">
          <exception class="java.lang.AssertionError">
            <message>
              <![CDATA[expected [false] but found [true]]]>
            </message>
            <full-stacktrace>
              <![CDATA[java.lang.AssertionError: expected [false] but found [true]
	at org.testng.Assert.fail(Assert.java:94)
	at org.testng.Assert.failNotEquals(Assert.java:494)
	at org.testng.Assert.assertEquals(Assert.java:123)
	at org.testng.Assert.assertEquals(Assert.java:286)
	at org.testng.Assert.assertEquals(Assert.java:296)
	at com.FCI.SWE.ServicesModels.Entitytest.chat_message(Entitytest.java:100)
	at sun.reflect.NativeMethodAccessorImpl.invoke0(Native Method)
	at sun.reflect.NativeMethodAccessorImpl.invoke(NativeMethodAccessorImpl.java:57)
	at sun.reflect.DelegatingMethodAccessorImpl.invoke(DelegatingMethodAccessorImpl.java:43)
	at java.lang.reflect.Method.invoke(Method.java:606)
	at org.testng.internal.MethodInvocationHelper.invokeMethod(MethodInvocationHelper.java:85)
	at org.testng.internal.Invoker.invokeMethod(Invoker.java:659)
	at org.testng.internal.Invoker.invokeTestMethod(Invoker.java:845)
	at org.testng.internal.Invoker.invokeTestMethods(Invoker.java:1153)
	at org.testng.internal.TestMethodWorker.invokeTestMethods(TestMethodWorker.java:124)
	at org.testng.internal.TestMethodWorker.run(TestMethodWorker.java:108)
	at org.testng.TestRunner.privateRun(TestRunner.java:771)
	at org.testng.TestRunner.run(TestRunner.java:621)
	at org.testng.SuiteRunner.runTest(SuiteRunner.java:352)
	at org.testng.SuiteRunner.runSequentially(SuiteRunner.java:347)
	at org.testng.SuiteRunner.privateRun(SuiteRunner.java:305)
	at org.testng.SuiteRunner.run(SuiteRunner.java:254)
	at org.testng.SuiteRunnerWorker.runSuite(SuiteRunnerWorker.java:52)
	at org.testng.SuiteRunnerWorker.run(SuiteRunnerWorker.java:86)
	at org.testng.TestNG.runSuitesSequentially(TestNG.java:1199)
	at org.testng.TestNG.runSuitesLocally(TestNG.java:1124)
	at org.testng.TestNG.run(TestNG.java:1032)
	at org.testng.remote.RemoteTestNG.run(RemoteTestNG.java:111)
	at org.testng.remote.RemoteTestNG.initAndRun(RemoteTestNG.java:204)
	at org.testng.remote.RemoteTestNG.main(RemoteTestNG.java:175)
]]>
            </full-stacktrace>
          </exception> <!-- java.lang.AssertionError -->
          <reporter-output>
          </reporter-output>
        </test-method> <!-- chat_message -->
        <test-method status="PASS" signature="creat_page()[pri:0, instance:com.FCI.SWE.ServicesModels.Entitytest@44a38527]" name="creat_page" duration-ms="164" started-at="2015-05-10T22:57:34Z" finished-at="2015-05-10T22:57:34Z">
          <reporter-output>
          </reporter-output>
        </test-method> <!-- creat_page -->
        <test-method status="FAIL" signature="createTimelinePost()[pri:0, instance:com.FCI.SWE.ServicesModels.Entitytest@44a38527]" name="createTimelinePost" duration-ms="3" started-at="2015-05-10T22:57:34Z" finished-at="2015-05-10T22:57:34Z">
          <exception class="java.lang.AssertionError">
            <message>
              <![CDATA[expected [false] but found [true]]]>
            </message>
            <full-stacktrace>
              <![CDATA[java.lang.AssertionError: expected [false] but found [true]
	at org.testng.Assert.fail(Assert.java:94)
	at org.testng.Assert.failNotEquals(Assert.java:494)
	at org.testng.Assert.assertEquals(Assert.java:123)
	at org.testng.Assert.assertEquals(Assert.java:286)
	at org.testng.Assert.assertEquals(Assert.java:296)
	at com.FCI.SWE.ServicesModels.Entitytest.createTimelinePost(Entitytest.java:127)
	at sun.reflect.NativeMethodAccessorImpl.invoke0(Native Method)
	at sun.reflect.NativeMethodAccessorImpl.invoke(NativeMethodAccessorImpl.java:57)
	at sun.reflect.DelegatingMethodAccessorImpl.invoke(DelegatingMethodAccessorImpl.java:43)
	at java.lang.reflect.Method.invoke(Method.java:606)
	at org.testng.internal.MethodInvocationHelper.invokeMethod(MethodInvocationHelper.java:85)
	at org.testng.internal.Invoker.invokeMethod(Invoker.java:659)
	at org.testng.internal.Invoker.invokeTestMethod(Invoker.java:845)
	at org.testng.internal.Invoker.invokeTestMethods(Invoker.java:1153)
	at org.testng.internal.TestMethodWorker.invokeTestMethods(TestMethodWorker.java:124)
	at org.testng.internal.TestMethodWorker.run(TestMethodWorker.java:108)
	at org.testng.TestRunner.privateRun(TestRunner.java:771)
	at org.testng.TestRunner.run(TestRunner.java:621)
	at org.testng.SuiteRunner.runTest(SuiteRunner.java:352)
	at org.testng.SuiteRunner.runSequentially(SuiteRunner.java:347)
	at org.testng.SuiteRunner.privateRun(SuiteRunner.java:305)
	at org.testng.SuiteRunner.run(SuiteRunner.java:254)
	at org.testng.SuiteRunnerWorker.runSuite(SuiteRunnerWorker.java:52)
	at org.testng.SuiteRunnerWorker.run(SuiteRunnerWorker.java:86)
	at org.testng.TestNG.runSuitesSequentially(TestNG.java:1199)
	at org.testng.TestNG.runSuitesLocally(TestNG.java:1124)
	at org.testng.TestNG.run(TestNG.java:1032)
	at org.testng.remote.RemoteTestNG.run(RemoteTestNG.java:111)
	at org.testng.remote.RemoteTestNG.initAndRun(RemoteTestNG.java:204)
	at org.testng.remote.RemoteTestNG.main(RemoteTestNG.java:175)
]]>
            </full-stacktrace>
          </exception> <!-- java.lang.AssertionError -->
          <reporter-output>
          </reporter-output>
        </test-method> <!-- createTimelinePost -->
        <test-method status="FAIL" signature="create_hashtag()[pri:0, instance:com.FCI.SWE.ServicesModels.Entitytest@44a38527]" name="create_hashtag" duration-ms="9" started-at="2015-05-10T22:57:34Z" finished-at="2015-05-10T22:57:34Z">
          <exception class="java.lang.AssertionError">
            <message>
              <![CDATA[expected [failed] but found [created]]]>
            </message>
            <full-stacktrace>
              <![CDATA[java.lang.AssertionError: expected [failed] but found [created]
	at org.testng.Assert.fail(Assert.java:94)
	at org.testng.Assert.failNotEquals(Assert.java:494)
	at org.testng.Assert.assertEquals(Assert.java:123)
	at org.testng.Assert.assertEquals(Assert.java:176)
	at org.testng.Assert.assertEquals(Assert.java:186)
	at com.FCI.SWE.ServicesModels.Entitytest.create_hashtag(Entitytest.java:137)
	at sun.reflect.NativeMethodAccessorImpl.invoke0(Native Method)
	at sun.reflect.NativeMethodAccessorImpl.invoke(NativeMethodAccessorImpl.java:57)
	at sun.reflect.DelegatingMethodAccessorImpl.invoke(DelegatingMethodAccessorImpl.java:43)
	at java.lang.reflect.Method.invoke(Method.java:606)
	at org.testng.internal.MethodInvocationHelper.invokeMethod(MethodInvocationHelper.java:85)
	at org.testng.internal.Invoker.invokeMethod(Invoker.java:659)
	at org.testng.internal.Invoker.invokeTestMethod(Invoker.java:845)
	at org.testng.internal.Invoker.invokeTestMethods(Invoker.java:1153)
	at org.testng.internal.TestMethodWorker.invokeTestMethods(TestMethodWorker.java:124)
	at org.testng.internal.TestMethodWorker.run(TestMethodWorker.java:108)
	at org.testng.TestRunner.privateRun(TestRunner.java:771)
	at org.testng.TestRunner.run(TestRunner.java:621)
	at org.testng.SuiteRunner.runTest(SuiteRunner.java:352)
	at org.testng.SuiteRunner.runSequentially(SuiteRunner.java:347)
	at org.testng.SuiteRunner.privateRun(SuiteRunner.java:305)
	at org.testng.SuiteRunner.run(SuiteRunner.java:254)
	at org.testng.SuiteRunnerWorker.runSuite(SuiteRunnerWorker.java:52)
	at org.testng.SuiteRunnerWorker.run(SuiteRunnerWorker.java:86)
	at org.testng.TestNG.runSuitesSequentially(TestNG.java:1199)
	at org.testng.TestNG.runSuitesLocally(TestNG.java:1124)
	at org.testng.TestNG.run(TestNG.java:1032)
	at org.testng.remote.RemoteTestNG.run(RemoteTestNG.java:111)
	at org.testng.remote.RemoteTestNG.initAndRun(RemoteTestNG.java:204)
	at org.testng.remote.RemoteTestNG.main(RemoteTestNG.java:175)
]]>
            </full-stacktrace>
          </exception> <!-- java.lang.AssertionError -->
          <reporter-output>
          </reporter-output>
        </test-method> <!-- create_hashtag -->
        <test-method status="FAIL" signature="getUser()[pri:0, instance:com.FCI.SWE.ServicesModels.Entitytest@44a38527]" name="getUser" duration-ms="3" started-at="2015-05-10T22:57:34Z" finished-at="2015-05-10T22:57:34Z">
          <exception class="java.lang.AssertionError">
            <message>
              <![CDATA[expected object to not be null]]>
            </message>
            <full-stacktrace>
              <![CDATA[java.lang.AssertionError: expected object to not be null
	at org.testng.Assert.fail(Assert.java:94)
	at org.testng.Assert.assertNotNull(Assert.java:404)
	at org.testng.Assert.assertNotNull(Assert.java:389)
	at com.FCI.SWE.ServicesModels.Entitytest.getUser(Entitytest.java:43)
	at sun.reflect.NativeMethodAccessorImpl.invoke0(Native Method)
	at sun.reflect.NativeMethodAccessorImpl.invoke(NativeMethodAccessorImpl.java:57)
	at sun.reflect.DelegatingMethodAccessorImpl.invoke(DelegatingMethodAccessorImpl.java:43)
	at java.lang.reflect.Method.invoke(Method.java:606)
	at org.testng.internal.MethodInvocationHelper.invokeMethod(MethodInvocationHelper.java:85)
	at org.testng.internal.Invoker.invokeMethod(Invoker.java:659)
	at org.testng.internal.Invoker.invokeTestMethod(Invoker.java:845)
	at org.testng.internal.Invoker.invokeTestMethods(Invoker.java:1153)
	at org.testng.internal.TestMethodWorker.invokeTestMethods(TestMethodWorker.java:124)
	at org.testng.internal.TestMethodWorker.run(TestMethodWorker.java:108)
	at org.testng.TestRunner.privateRun(TestRunner.java:771)
	at org.testng.TestRunner.run(TestRunner.java:621)
	at org.testng.SuiteRunner.runTest(SuiteRunner.java:352)
	at org.testng.SuiteRunner.runSequentially(SuiteRunner.java:347)
	at org.testng.SuiteRunner.privateRun(SuiteRunner.java:305)
	at org.testng.SuiteRunner.run(SuiteRunner.java:254)
	at org.testng.SuiteRunnerWorker.runSuite(SuiteRunnerWorker.java:52)
	at org.testng.SuiteRunnerWorker.run(SuiteRunnerWorker.java:86)
	at org.testng.TestNG.runSuitesSequentially(TestNG.java:1199)
	at org.testng.TestNG.runSuitesLocally(TestNG.java:1124)
	at org.testng.TestNG.run(TestNG.java:1032)
	at org.testng.remote.RemoteTestNG.run(RemoteTestNG.java:111)
	at org.testng.remote.RemoteTestNG.initAndRun(RemoteTestNG.java:204)
	at org.testng.remote.RemoteTestNG.main(RemoteTestNG.java:175)
]]>
            </full-stacktrace>
          </exception> <!-- java.lang.AssertionError -->
          <reporter-output>
          </reporter-output>
        </test-method> <!-- getUser -->
        <test-method status="FAIL" signature="getrequest()[pri:0, instance:com.FCI.SWE.ServicesModels.Entitytest@44a38527]" name="getrequest" duration-ms="1" started-at="2015-05-10T22:57:34Z" finished-at="2015-05-10T22:57:34Z">
          <exception class="java.lang.NullPointerException">
            <full-stacktrace>
              <![CDATA[java.lang.NullPointerException
	at com.FCI.SWE.ServicesModels.UserEntity.getrequest(UserEntity.java:206)
	at com.FCI.SWE.ServicesModels.Entitytest.getrequest(Entitytest.java:58)
	at sun.reflect.NativeMethodAccessorImpl.invoke0(Native Method)
	at sun.reflect.NativeMethodAccessorImpl.invoke(NativeMethodAccessorImpl.java:57)
	at sun.reflect.DelegatingMethodAccessorImpl.invoke(DelegatingMethodAccessorImpl.java:43)
	at java.lang.reflect.Method.invoke(Method.java:606)
	at org.testng.internal.MethodInvocationHelper.invokeMethod(MethodInvocationHelper.java:85)
	at org.testng.internal.Invoker.invokeMethod(Invoker.java:659)
	at org.testng.internal.Invoker.invokeTestMethod(Invoker.java:845)
	at org.testng.internal.Invoker.invokeTestMethods(Invoker.java:1153)
	at org.testng.internal.TestMethodWorker.invokeTestMethods(TestMethodWorker.java:124)
	at org.testng.internal.TestMethodWorker.run(TestMethodWorker.java:108)
	at org.testng.TestRunner.privateRun(TestRunner.java:771)
	at org.testng.TestRunner.run(TestRunner.java:621)
	at org.testng.SuiteRunner.runTest(SuiteRunner.java:352)
	at org.testng.SuiteRunner.runSequentially(SuiteRunner.java:347)
	at org.testng.SuiteRunner.privateRun(SuiteRunner.java:305)
	at org.testng.SuiteRunner.run(SuiteRunner.java:254)
	at org.testng.SuiteRunnerWorker.runSuite(SuiteRunnerWorker.java:52)
	at org.testng.SuiteRunnerWorker.run(SuiteRunnerWorker.java:86)
	at org.testng.TestNG.runSuitesSequentially(TestNG.java:1199)
	at org.testng.TestNG.runSuitesLocally(TestNG.java:1124)
	at org.testng.TestNG.run(TestNG.java:1032)
	at org.testng.remote.RemoteTestNG.run(RemoteTestNG.java:111)
	at org.testng.remote.RemoteTestNG.initAndRun(RemoteTestNG.java:204)
	at org.testng.remote.RemoteTestNG.main(RemoteTestNG.java:175)
]]>
            </full-stacktrace>
          </exception> <!-- java.lang.NullPointerException -->
          <reporter-output>
          </reporter-output>
        </test-method> <!-- getrequest -->
        <test-method status="FAIL" signature="savepost()[pri:0, instance:com.FCI.SWE.ServicesModels.Entitytest@44a38527]" name="savepost" duration-ms="5" started-at="2015-05-10T22:57:34Z" finished-at="2015-05-10T22:57:34Z">
          <exception class="java.lang.AssertionError">
            <message>
              <![CDATA[expected [false] but found [true]]]>
            </message>
            <full-stacktrace>
              <![CDATA[java.lang.AssertionError: expected [false] but found [true]
	at org.testng.Assert.fail(Assert.java:94)
	at org.testng.Assert.failNotEquals(Assert.java:494)
	at org.testng.Assert.assertEquals(Assert.java:123)
	at org.testng.Assert.assertEquals(Assert.java:286)
	at org.testng.Assert.assertEquals(Assert.java:296)
	at com.FCI.SWE.ServicesModels.Entitytest.savepost(Entitytest.java:119)
	at sun.reflect.NativeMethodAccessorImpl.invoke0(Native Method)
	at sun.reflect.NativeMethodAccessorImpl.invoke(NativeMethodAccessorImpl.java:57)
	at sun.reflect.DelegatingMethodAccessorImpl.invoke(DelegatingMethodAccessorImpl.java:43)
	at java.lang.reflect.Method.invoke(Method.java:606)
	at org.testng.internal.MethodInvocationHelper.invokeMethod(MethodInvocationHelper.java:85)
	at org.testng.internal.Invoker.invokeMethod(Invoker.java:659)
	at org.testng.internal.Invoker.invokeTestMethod(Invoker.java:845)
	at org.testng.internal.Invoker.invokeTestMethods(Invoker.java:1153)
	at org.testng.internal.TestMethodWorker.invokeTestMethods(TestMethodWorker.java:124)
	at org.testng.internal.TestMethodWorker.run(TestMethodWorker.java:108)
	at org.testng.TestRunner.privateRun(TestRunner.java:771)
	at org.testng.TestRunner.run(TestRunner.java:621)
	at org.testng.SuiteRunner.runTest(SuiteRunner.java:352)
	at org.testng.SuiteRunner.runSequentially(SuiteRunner.java:347)
	at org.testng.SuiteRunner.privateRun(SuiteRunner.java:305)
	at org.testng.SuiteRunner.run(SuiteRunner.java:254)
	at org.testng.SuiteRunnerWorker.runSuite(SuiteRunnerWorker.java:52)
	at org.testng.SuiteRunnerWorker.run(SuiteRunnerWorker.java:86)
	at org.testng.TestNG.runSuitesSequentially(TestNG.java:1199)
	at org.testng.TestNG.runSuitesLocally(TestNG.java:1124)
	at org.testng.TestNG.run(TestNG.java:1032)
	at org.testng.remote.RemoteTestNG.run(RemoteTestNG.java:111)
	at org.testng.remote.RemoteTestNG.initAndRun(RemoteTestNG.java:204)
	at org.testng.remote.RemoteTestNG.main(RemoteTestNG.java:175)
]]>
            </full-stacktrace>
          </exception> <!-- java.lang.AssertionError -->
          <reporter-output>
          </reporter-output>
        </test-method> <!-- savepost -->
        <test-method status="PASS" signature="saveuser()[pri:0, instance:com.FCI.SWE.ServicesModels.Entitytest@44a38527]" name="saveuser" duration-ms="20" started-at="2015-05-10T22:57:34Z" finished-at="2015-05-10T22:57:34Z">
          <reporter-output>
          </reporter-output>
        </test-method> <!-- saveuser -->
        <test-method status="FAIL" signature="search()[pri:0, instance:com.FCI.SWE.ServicesModels.Entitytest@44a38527]" name="search" duration-ms="5" started-at="2015-05-10T22:57:34Z" finished-at="2015-05-10T22:57:34Z">
          <exception class="java.lang.NullPointerException">
            <full-stacktrace>
              <![CDATA[java.lang.NullPointerException
	at com.FCI.SWE.ServicesModels.UserEntity.search(UserEntity.java:239)
	at com.FCI.SWE.ServicesModels.Entitytest.search(Entitytest.java:63)
	at sun.reflect.NativeMethodAccessorImpl.invoke0(Native Method)
	at sun.reflect.NativeMethodAccessorImpl.invoke(NativeMethodAccessorImpl.java:57)
	at sun.reflect.DelegatingMethodAccessorImpl.invoke(DelegatingMethodAccessorImpl.java:43)
	at java.lang.reflect.Method.invoke(Method.java:606)
	at org.testng.internal.MethodInvocationHelper.invokeMethod(MethodInvocationHelper.java:85)
	at org.testng.internal.Invoker.invokeMethod(Invoker.java:659)
	at org.testng.internal.Invoker.invokeTestMethod(Invoker.java:845)
	at org.testng.internal.Invoker.invokeTestMethods(Invoker.java:1153)
	at org.testng.internal.TestMethodWorker.invokeTestMethods(TestMethodWorker.java:124)
	at org.testng.internal.TestMethodWorker.run(TestMethodWorker.java:108)
	at org.testng.TestRunner.privateRun(TestRunner.java:771)
	at org.testng.TestRunner.run(TestRunner.java:621)
	at org.testng.SuiteRunner.runTest(SuiteRunner.java:352)
	at org.testng.SuiteRunner.runSequentially(SuiteRunner.java:347)
	at org.testng.SuiteRunner.privateRun(SuiteRunner.java:305)
	at org.testng.SuiteRunner.run(SuiteRunner.java:254)
	at org.testng.SuiteRunnerWorker.runSuite(SuiteRunnerWorker.java:52)
	at org.testng.SuiteRunnerWorker.run(SuiteRunnerWorker.java:86)
	at org.testng.TestNG.runSuitesSequentially(TestNG.java:1199)
	at org.testng.TestNG.runSuitesLocally(TestNG.java:1124)
	at org.testng.TestNG.run(TestNG.java:1032)
	at org.testng.remote.RemoteTestNG.run(RemoteTestNG.java:111)
	at org.testng.remote.RemoteTestNG.initAndRun(RemoteTestNG.java:204)
	at org.testng.remote.RemoteTestNG.main(RemoteTestNG.java:175)
]]>
            </full-stacktrace>
          </exception> <!-- java.lang.NullPointerException -->
          <reporter-output>
          </reporter-output>
        </test-method> <!-- search -->
        <test-method status="PASS" signature="sendgroup_mesg()[pri:0, instance:com.FCI.SWE.ServicesModels.Entitytest@44a38527]" name="sendgroup_mesg" duration-ms="4" started-at="2015-05-10T22:57:34Z" finished-at="2015-05-10T22:57:34Z">
          <reporter-output>
          </reporter-output>
        </test-method> <!-- sendgroup_mesg -->
        <test-method status="FAIL" signature="sendmessage()[pri:0, instance:com.FCI.SWE.ServicesModels.Entitytest@44a38527]" name="sendmessage" duration-ms="2" started-at="2015-05-10T22:57:34Z" finished-at="2015-05-10T22:57:34Z">
          <exception class="java.lang.AssertionError">
            <message>
              <![CDATA[expected [false] but found [true]]]>
            </message>
            <full-stacktrace>
              <![CDATA[java.lang.AssertionError: expected [false] but found [true]
	at org.testng.Assert.fail(Assert.java:94)
	at org.testng.Assert.failNotEquals(Assert.java:494)
	at org.testng.Assert.assertEquals(Assert.java:123)
	at org.testng.Assert.assertEquals(Assert.java:286)
	at org.testng.Assert.assertEquals(Assert.java:296)
	at com.FCI.SWE.ServicesModels.Entitytest.sendmessage(Entitytest.java:85)
	at sun.reflect.NativeMethodAccessorImpl.invoke0(Native Method)
	at sun.reflect.NativeMethodAccessorImpl.invoke(NativeMethodAccessorImpl.java:57)
	at sun.reflect.DelegatingMethodAccessorImpl.invoke(DelegatingMethodAccessorImpl.java:43)
	at java.lang.reflect.Method.invoke(Method.java:606)
	at org.testng.internal.MethodInvocationHelper.invokeMethod(MethodInvocationHelper.java:85)
	at org.testng.internal.Invoker.invokeMethod(Invoker.java:659)
	at org.testng.internal.Invoker.invokeTestMethod(Invoker.java:845)
	at org.testng.internal.Invoker.invokeTestMethods(Invoker.java:1153)
	at org.testng.internal.TestMethodWorker.invokeTestMethods(TestMethodWorker.java:124)
	at org.testng.internal.TestMethodWorker.run(TestMethodWorker.java:108)
	at org.testng.TestRunner.privateRun(TestRunner.java:771)
	at org.testng.TestRunner.run(TestRunner.java:621)
	at org.testng.SuiteRunner.runTest(SuiteRunner.java:352)
	at org.testng.SuiteRunner.runSequentially(SuiteRunner.java:347)
	at org.testng.SuiteRunner.privateRun(SuiteRunner.java:305)
	at org.testng.SuiteRunner.run(SuiteRunner.java:254)
	at org.testng.SuiteRunnerWorker.runSuite(SuiteRunnerWorker.java:52)
	at org.testng.SuiteRunnerWorker.run(SuiteRunnerWorker.java:86)
	at org.testng.TestNG.runSuitesSequentially(TestNG.java:1199)
	at org.testng.TestNG.runSuitesLocally(TestNG.java:1124)
	at org.testng.TestNG.run(TestNG.java:1032)
	at org.testng.remote.RemoteTestNG.run(RemoteTestNG.java:111)
	at org.testng.remote.RemoteTestNG.initAndRun(RemoteTestNG.java:204)
	at org.testng.remote.RemoteTestNG.main(RemoteTestNG.java:175)
]]>
            </full-stacktrace>
          </exception> <!-- java.lang.AssertionError -->
          <reporter-output>
          </reporter-output>
        </test-method> <!-- sendmessage -->
        <test-method status="FAIL" signature="sendrequest()[pri:0, instance:com.FCI.SWE.ServicesModels.Entitytest@44a38527]" name="sendrequest" duration-ms="2" started-at="2015-05-10T22:57:34Z" finished-at="2015-05-10T22:57:34Z">
          <exception class="java.lang.AssertionError">
            <message>
              <![CDATA[expected [false] but found [true]]]>
            </message>
            <full-stacktrace>
              <![CDATA[java.lang.AssertionError: expected [false] but found [true]
	at org.testng.Assert.fail(Assert.java:94)
	at org.testng.Assert.failNotEquals(Assert.java:494)
	at org.testng.Assert.assertEquals(Assert.java:123)
	at org.testng.Assert.assertEquals(Assert.java:286)
	at org.testng.Assert.assertEquals(Assert.java:296)
	at com.FCI.SWE.ServicesModels.Entitytest.sendrequest(Entitytest.java:55)
	at sun.reflect.NativeMethodAccessorImpl.invoke0(Native Method)
	at sun.reflect.NativeMethodAccessorImpl.invoke(NativeMethodAccessorImpl.java:57)
	at sun.reflect.DelegatingMethodAccessorImpl.invoke(DelegatingMethodAccessorImpl.java:43)
	at java.lang.reflect.Method.invoke(Method.java:606)
	at org.testng.internal.MethodInvocationHelper.invokeMethod(MethodInvocationHelper.java:85)
	at org.testng.internal.Invoker.invokeMethod(Invoker.java:659)
	at org.testng.internal.Invoker.invokeTestMethod(Invoker.java:845)
	at org.testng.internal.Invoker.invokeTestMethods(Invoker.java:1153)
	at org.testng.internal.TestMethodWorker.invokeTestMethods(TestMethodWorker.java:124)
	at org.testng.internal.TestMethodWorker.run(TestMethodWorker.java:108)
	at org.testng.TestRunner.privateRun(TestRunner.java:771)
	at org.testng.TestRunner.run(TestRunner.java:621)
	at org.testng.SuiteRunner.runTest(SuiteRunner.java:352)
	at org.testng.SuiteRunner.runSequentially(SuiteRunner.java:347)
	at org.testng.SuiteRunner.privateRun(SuiteRunner.java:305)
	at org.testng.SuiteRunner.run(SuiteRunner.java:254)
	at org.testng.SuiteRunnerWorker.runSuite(SuiteRunnerWorker.java:52)
	at org.testng.SuiteRunnerWorker.run(SuiteRunnerWorker.java:86)
	at org.testng.TestNG.runSuitesSequentially(TestNG.java:1199)
	at org.testng.TestNG.runSuitesLocally(TestNG.java:1124)
	at org.testng.TestNG.run(TestNG.java:1032)
	at org.testng.remote.RemoteTestNG.run(RemoteTestNG.java:111)
	at org.testng.remote.RemoteTestNG.initAndRun(RemoteTestNG.java:204)
	at org.testng.remote.RemoteTestNG.main(RemoteTestNG.java:175)
]]>
            </full-stacktrace>
          </exception> <!-- java.lang.AssertionError -->
          <reporter-output>
          </reporter-output>
        </test-method> <!-- sendrequest -->
        <test-method status="PASS" signature="tearDown()[pri:0, instance:com.FCI.SWE.ServicesModels.Entitytest@44a38527]" name="tearDown" is-config="true" duration-ms="258" started-at="2015-05-10T22:57:34Z" finished-at="2015-05-10T22:57:34Z">
          <reporter-output>
          </reporter-output>
        </test-method> <!-- tearDown -->
      </class> <!-- com.FCI.SWE.ServicesModels.Entitytest -->
    </test> <!-- Default test -->
  </suite> <!-- Default suite -->
</testng-results>
